<?xml version="1.0"?>
<robot xmlns:xacro="http://www.ros.org/wiki/xacro" name="humanbot">

    <!-- define materials -->

    <xacro:macro name="material_visual_red" params="">
        <material name="red">
            <color rgba="0.8 0 0 1"/>
        </material>
    </xacro:macro>

    <xacro:macro name="material_visual_torso_red" params="">
        <material name="torso_red">
            <color rgba="0.8 0 0 0.6"/>
        </material>
    </xacro:macro>

    <xacro:macro name="material_visual_green" params="">
        <material name="green">
            <color rgba="0 0.8 0 1"/>
        </material>
    </xacro:macro>

    <xacro:macro name="material_visual_blue" params="">
        <material name="blue">
            <color rgba="0 0 0.8 1"/>
        </material>
    </xacro:macro>

    <xacro:macro name="material_visual_grey" params="">
        <material name="grey">
            <color rgba="0.7 0.7 0.7 1"/>
        </material>
    </xacro:macro>

    <!-- define head and torso -->

    <xacro:macro name="head_torso_part" params="">

        <!-- define base_link -->

        <link name="base_link">
        
            <visual>
                <origin rpy="0 0 0" xyz="0 0 0.005"/>
                <geometry>
                    <box size="0.01 0.01 0.01"/>
                </geometry>
                <xacro:material_visual_grey />
            </visual>

        </link>


        <!-- define torso_link -->

        <link name="torso_link">

            <visual>
                <origin rpy="0 0 0" xyz="0 0 0.04"/>
                <geometry>
                    <box size="0.05 0.08 0.08"/>
                </geometry>
                <xacro:material_visual_torso_red />
            </visual>

        </link>

        <!-- define base_torso_joint -->

        <joint name="base_torso_joint" type="fixed">

            <parent link="base_link"/>
            <child link="torso_link"/>
            <origin xyz="0 0 0" rpy="0 0 0"/>

        </joint>

        <!-- define neck_link -->

        <link name="neck_link">

            <visual>
                <origin rpy="0 0 0" xyz="0 0 0.0075"/>
                <geometry>
                    <cylinder length="0.015" radius="0.015"/>
                </geometry>
                <xacro:material_visual_green />
            </visual>

        </link>

        <!-- define torso_neck_joint -->

        <joint name="torso_neck_joint" type="revolute">

            <parent link="torso_link"/>
            <child link="neck_link"/>
            <origin xyz="0 0 0.08" rpy="0 0 0"/>
            <limit lower="-1.5" upper="1.5" effort="1.0" velocity="0.005"/>
            <axis xyz="0 0 1"/>

        </joint>

        <!-- define head_link -->

        <link name="head_link">

            <visual>
                <origin rpy="0 0 0" xyz="0 0 0"/>
                <geometry>
                    <sphere radius="0.03"/>
                </geometry>
                <xacro:material_visual_red />
            </visual>

        </link>

        <!-- define neck_head_joint -->

        <joint name="neck_head_joint" type="fixed">

            <parent link="neck_link"/>
            <child link="head_link"/>
            <origin xyz="0 0 0.04" rpy="0 0 0"/>

        </joint>

    </xacro:macro>

    <!-- define shoulder up -->

    <xacro:macro name="shoulder_up_part" params="position *origin">

        <!-- define shoulder_up_link -->

        <link name="${position}_shoulder_up_link">

            <visual>
                <origin rpy="0 0 0" xyz="0 0 0"/>
                <geometry>
                    <cylinder length="0.02" radius="0.012"/>
                </geometry>
                <material name="green"/>
            </visual>

        </link>

        <!-- define torso_shoulderup_joint -->

        <joint name="torso_${position}shoulderup_joint" type="revolute">

            <parent link="torso_link"/>
            <child link="${position}_shoulder_up_link"/>
            <xacro:insert_block name="origin"/>
            <limit lower="0" upper="1.5" effort="1.0" velocity="0.005"/>
            <axis xyz="0 0 1"/>

        </joint>

    </xacro:macro>

    <!-- define shoulder forward -->

    <xacro:macro name="shoulder_forward_part" params="position *origin">

        <!-- define shoulder_forward_link -->

        <link name="${position}_shoulder_forward_link">

            <visual>
                <origin rpy="0 0 0" xyz="0 0 0"/>
                <geometry>
                    <cylinder length="0.02" radius="0.01"/>
                </geometry>
                <xacro:material_visual_blue />
            </visual>

        </link>

        <!-- define shoulder_up_forwar_joint -->

        <joint name="${position}_shoulder_up_forwar_joint" type="revolute">

            <parent link="${position}_shoulder_up_link"/>
            <child link="${position}_shoulder_forward_link"/>
            <xacro:insert_block name="origin" />
            <limit lower="-1.5" upper="3" effort="1.0" velocity="0.005"/>    
            <axis xyz="0 0 1"/>   

        </joint>

    </xacro:macro>

    <!-- define upperarm part -->

    <xacro:macro name="upperarm_part" params="position visual_z *origin">

        <!-- define upperarm_link -->

        <link name="${position}_upperarm_link">

            <visual>
                <origin rpy="0 0 0" xyz="0 0 ${visual_z}"/>
                <geometry>
                    <cylinder length="0.08" radius="0.01"/>
                </geometry>
                <xacro:material_visual_red />
            </visual>

        </link>

        <!-- define shoulderforward_upperarm_joint -->

        <joint name="${position}_shoulderforward_upperarm_joint" type="revolute">

            <parent link="${position}_shoulder_forward_link"/>
            <child link="${position}_upperarm_link"/>
            <xacro:insert_block name="origin" />
            <limit lower="-1.5" upper="0.5" effort="1.0" velocity="0.005"/>
            <axis xyz="0 0 1"/>

        </joint>

    </xacro:macro>

    <!-- define elbow part -->

    <xacro:macro name="elbow_part" params="position *origin">

        <!-- define elbow_link -->

        <link name="${position}_elbow_link">

            <visual>
                <origin rpy="0 0 0" xyz="0 0 0"/>
                <geometry>
                    <sphere radius="0.01"/>
                </geometry>
                <xacro:material_visual_green />
            </visual>

        </link>

        <!-- define elbow_upperarm_joint -->

        <joint name="${position}_elbow_upperarm_joint" type="revolute">

            <parent link="${position}_upperarm_link"/>
            <child link="${position}_elbow_link"/>
            <xacro:insert_block name="origin" />
            <limit lower="-3" upper="0" effort="1.0" velocity="0.005"/>
            <axis xyz="1 0 0"/>

        </joint>

    </xacro:macro>

    <!-- define lowerarm part -->

    <xacro:macro name="lowerarm_part" params="position visual_z *origin">

        <!-- define lowerarm_link -->

        <link name="${position}_lowerarm_link">

            <visual>
                <origin rpy="0 0 0" xyz="0 0 ${visual_z}"/>
                <geometry>
                    <cylinder length="0.08" radius="0.01"/>
                </geometry>
                <xacro:material_visual_red/>
            </visual>

        </link>

        <!-- define elbow_lowerarm_joint -->

        <joint name="${position}_elbow_lowerarm_joint" type="revolute">

            <parent link="${position}_elbow_link"/>
            <child link="${position}_lowerarm_link"/>
            <xacro:insert_block name="origin" />
            <limit lower="-0.2" upper="1.57" effort="1.0" velocity="0.005"/>
            <axis xyz="0 0 1"/>

        </joint>

    </xacro:macro>

    <!-- define wrist part -->

    <xacro:macro name="wrist_part" params="position *origin">

        <!-- define wrist_link -->

        <link name="${position}_wrist_link">
            <visual>
                <origin rpy="0 0 0" xyz="0 0 0"/>
                <geometry>
                    <sphere radius="0.01"/>
                </geometry>
                <xacro:material_visual_blue />
            </visual>
        </link>

        <!-- define lowerarm_wrist_joint -->

        <joint name="${position}_lowerarm_wrist_link" type="revolute">

            <parent link="${position}_lowerarm_link"/>
            <child link="${position}_wrist_link"/>
            <xacro:insert_block name="origin" />
            <limit lower="-0.5" upper="0.5" effort="1.0" velocity="0.005"/>
            <axis xyz="1 0 0"/>

        </joint>
    
    </xacro:macro>

    <!-- define hand part -->

    <xacro:macro name="hand_part" params="position *origin">

        <!-- define hand_link -->

        <link name="${position}_hand_link">

            <visual>
                <origin rpy="0 0 0" xyz="0 0 0.015"/>
                <geometry>
                    <box size="0.03 0.015 0.04"/>
                </geometry>
                <xacro:material_visual_red />
            </visual>

        </link>

        <!-- define lowerarm_hand_joint -->

        <joint name="${position}_wrist_hand_joint" type="revolute">

            <parent link="${position}_wrist_link"/>
            <child link="${position}_hand_link"/>
            <xacro:insert_block name="origin" />
            <limit lower="-1.5" upper="1.5" effort="1.0" velocity="0.005"/>
            <axis xyz="1 0 0"/>

        </joint>

    </xacro:macro>

    <!-- define left arm -->
    
    <xacro:macro name="left_arm_part" params="">

        <!-- apply left shoulder up -->
        <xacro:shoulder_up_part position="left">
            <origin xyz="0 0.05 0.07" rpy="0 1.57 0"/>
        </xacro:shoulder_up_part>

        <!-- apply left shoulder forward -->
        <xacro:shoulder_forward_part position="left">
            <origin xyz="0.015 0.012 0" rpy="1.57 0 0"/>
        </xacro:shoulder_forward_part>

        <!-- apply left upperarm -->
        <xacro:upperarm_part position="left" visual_z="0.04">
            <origin xyz="0 0 0" rpy="0 1.57 0"/>
        </xacro:upperarm_part>

        <!-- apply left elbow -->
        <xacro:elbow_part position="left">
            <origin xyz="0 0 0.085" rpy="0 0 0"/>
        </xacro:elbow_part>

        <!-- apply left lowerarm -->
        <xacro:lowerarm_part position="left" visual_z="0.04">
            <origin xyz="0 0 0.005" rpy="0 0 0"/>
        </xacro:lowerarm_part>

        <!-- apply left wrist -->
        <xacro:wrist_part position="left">
            <origin xyz="0 0 0.085" rpy="0 0 0"/>
        </xacro:wrist_part>

        <!-- apply left hand -->
        <xacro:hand_part position="left">
            <origin xyz="0 0 0.01" rpy="0 0 1.57"/>
        </xacro:hand_part>

    </xacro:macro>

    <!-- define right arm -->

    <xacro:macro name="right_arm_part" params="">

        <!-- apply right shoulder up -->
        <xacro:shoulder_up_part position="right">
            <origin xyz="0 -0.05 0.07" rpy="3.14 1.57 0"/>
        </xacro:shoulder_up_part>

        <!-- apply right shoulder forward -->
        <xacro:shoulder_forward_part position="right">
            <origin xyz="0.015 0.012 0" rpy="-1.57 0 0"/>
        </xacro:shoulder_forward_part>

        <!-- apply right upperarm -->
        <xacro:upperarm_part position="right" visual_z="-0.04">
            <origin xyz="0 0 0" rpy="0 -1.57 0"/>
        </xacro:upperarm_part>

        <!-- apply right elbow -->
        <xacro:elbow_part position="right">
            <origin xyz="0 0 -0.085" rpy="0 3.14 0"/>
        </xacro:elbow_part>

        <!-- apply right lowerarm -->
        <xacro:lowerarm_part position="right" visual_z="-0.04">
            <origin xyz="0 0 0.005" rpy="0 3.14 0"/>
        </xacro:lowerarm_part>

        <!-- apply right wrist -->
        <xacro:wrist_part position="right">
            <origin xyz="0 0 -0.085" rpy="0 3.14 0"/>
        </xacro:wrist_part>

        <!-- apply right hand -->
        <xacro:hand_part position="right">
            <origin xyz="0 0 0.01" rpy="0 0 -1.57"/>
        </xacro:hand_part>

    </xacro:macro>

    <!-- define the whole body -->

    <xacro:macro name="whole_humanbot" params="">

        <!-- apply head and torso -->
        <xacro:head_torso_part />

        <!-- apply left arm -->
        <xacro:left_arm_part />

        <!-- apply right arm -->
        <xacro:right_arm_part />

        <!-- <xacro:arm_part /> -->
    </xacro:macro>

    <!-- apply whole body -->

    <xacro:whole_humanbot />

</robot>